Workbook

Sheet 신청서
A1: 서식2 | C1: 채무조정신청서
A3: 재기지원센터 채무조정 신청서
A5: 신청번호 : | C5: =온라인신청사항!D2
A6: 신청인 정보 | B6: 성명 | D6: =온라인신청사항!H2 | F6: 생년월일 | H6: =DATEDIF(I6,DATE(2025,1,1),"Y") | I6: =온라인신청사항!I2
B7: 업체명 | D7: =온라인신청사항!O2 | F7: 업태/종목 | H7: =온라인신청사항!T2
B8: 이메일 | D8: =온라인신청사항!M2 | F8: 연락처(H.P) | H8: =온라인신청사항!L2
H9: =온라인신청사항!K2
B10: 사업장주소 | D10: =온라인신청사항!Q2&", "&온라인신청사항!R2
B11: 사업유지현황 | D11: =온라인신청사항!N2 | F11: 성별 | H11: =온라인신청사항!J2
B12: 자문희망일자 | D12: =온라인신청사항!Y2 | F12: 상담신청유형 | H12: =온라인신청사항!X2
A13: 접 수 내 용
A14: 제목 | C14: =온라인신청사항!Z2
A15: 피해 및 문의내용 | C15: 사업으루더이상영위하기가힘들고 빚만늘고있는상황이며 더이상 영위하기가 어렵다는 판단하에 폐업신청을한상황입니다 소상공인으로 새출발기금긴청했으나 폐업하면서 채무조정액을 갚지못할상황이라 신청합니다 또한 폐업후세무신고등 지원원합니다
A19: 위의 내용이 사실임을 확인하며 법률자문신청서를 제출합니다.
A21: =온라인신청사항!V2
A24: 신 청 인 : | G24: =온라인신청사항!H2 | I24: (인)
A25: 소상공인시장진흥공단 이사장 귀하
A26: * 첨부하여 제출할 서류 1. 개인정보 수집·이용 및 제공 동의서 1부.
A27: 2. 증빙서류 (사업자등록증 또는 폐업사실증명원) 1부.
A29: 담당자정보 및 의견 | C29: 담당센터 | E29: =온라인신청사항!F2 | G29: 담당자 | I29: =온라인신청사항!G2
C30: 이메일 | G30: 연락처

Sheet 상담일지
A1: 서식2-1 | C1: 채무조정 상담일지
A3: 채무조정 상담일지
A5: 신청인 정보 | B5: 성명 | D5: 김경순 | F5: 생년월일 | H5: 42 | I5: 1984년생
B6: 업체명 | F6: 업태/종목
B7: 이메일 | F7: 연락처(H.P) | H7: 010-1234-5678
H8: =신청서!H9
B9: 사업장주소
B10: 사업유지현황 | F10: 성별
A11: 신용분석사 | E11: 담당변호사 | H11: 상담사
A13: 상담일지 | B13: 상담 일 | D13: 상담 내용
B14: 2026. 03. 17 | D14: 신청인의 연락처(핸드폰)로 상담완료 | L14: <- '상담일'은 날자만(예, 4-13) 입력
B15: 2026. 03. 17 | D15: 연체 여부 3개월 이상 연체(부실) 가. 신청인의 채무증대사유 신청인은 근로소득에 종사하고 있으며, 현재 총 채무 1.48억원이 있음. 채무 내역: 신용대출 1.48억원 현재 월 소득 200만원이며, 1인 가구 기준 생계비 1,538,543원을 초과하여 가용자금은 월 461,457원임. 나. 특이사항 특이사항 없음 다. 평가 및 의견 상기 내용을 종합적으로 검토한 결과, 신청인은 개인회생 절차가 가장 적합한 것으로 판단됨. 신청인의 월 소득 200만원에서 1인 가구 생계비 1,538,543원을 공제한 가용자금 461,457원이 발생하여 개인회생 변제계획 수립이 가능함. 예상 변제금 총 1,661만원, 월 변제액 461,457원, 예상 감면율 88.7%로 채무 부담을 크게 경감할 수 있음.
A37: <채무 사항>
A38: 채무종류 | D38: 금액(만원) | E38: 비고 | F38: 재산의 종류 | H38: 금액(만원) | I38: 비고
A39: 신용대출 | D39: 14750 | F39: 거주지 보증금
A40: 담보대출 | F40: 소유 부동산
A41: 세금 | F41: 배우자 부동산
A42: 사채 | F42: 자동차
A43: 물품대금 | F43: 해약(예상) 환급금
A44: 기타 | F44: 기타
A45: 채무 총액 : | D45: 14750 | F45: 재산 총계 :
A47: 채무 증대 사유 | I47: 금액(만원)
A48: 사업개시일 | C48: 업종 | E48: 폐업일자 | F48: 보증금 | G48: 월세 | H48: 월세미납 | I48: 집기,비품처분
A49: 2021년 | C49: 피부관리샵 | E49: 12월 폐업 | F49: 1000 | G49: 90 | I49: 0
A50: * 폐업 후 친인척이 사업을 개시하거나 보증금 회수, 집기 및 비품 처분내역 유의
A52: <소득 및 직업사항>
A53: 소득의 종류 | C53: 금액(만원) | E53: 직업 및 소득원
A54: 근로소득 | C54: 200
A56: <가족관계>
A57: 혼인관계 | C57: 미혼 | D57: 부양가족수 | E57: 0 | F57: (미성년자녀 | H57: 65세이상 | I57: 0
A59: <특기사항>
A60: [주식/가상화폐손실 규모] | F60: 없음
A61: [회생/파산 경험 및 면책경과 여부(배우자 포함)] | F61: 없음
A62: [정신적/신체적 치료 내용] | F62: 없음
A63: [기타]
A64: 신청인 진술사항
A66: [채무상황 상세내역]
A68: 채무종류 | D68: 금액(만원) | E68: 사용처 또는 발생사유
A69: 새출발기금
A70: 임차보증금
...

Sheet 평가표
A1: 서식2-3 | C1: 채무조정 평가·판정서
A3: 채무조정 신용평가 및 판정서
A5: 신청인 | B5: 이 름 | C5: 김경순 | D5: 생년월일 | E5: 1984년생 | F5: 전화번호 | G5: 010-1234-5678
B6: 업 체 명 | E6: 업 종
B7: 사업상태 | E7: 관할센터
A9: 담당 | B9: 신용분석사 | D9: 변호사 | F9: 사무원
A10: 평가 | B10: 변호사 | D10: 변호사 | F10: 변호사
B12: 평 가 항 목 | F12: 해당여부 | G12: 후속 프로세스 | I12: 효과 | J12: 구체적 조정 내용
A13: 1. | B13: 개인파산 신청대상 여부(법 제305조 제1항)
B14: ✓ 채무자의 연령, 직업 및 경력, 자격 또는 기술, 노동능력, 가족관계, 재산·부채의 내역 및 규모 등을 종합적으로 고려하여, 채무자의 재산, 신용, 수입에 의하더라도 채무의 일반적·계속적 변제가 불가능 하다고 객관적으로 판단됨(대법원 2009. 3. 2.자 2008마1651 결정). | G14: 적용 안함
B15: ✓ 소득부족 상태이며, 채무자 명의의 모든 재산을 환가하더라도 부채를 전액 변제할 수 없음(총부채>총재산)
B16: ✓ 개인파산 면책 확정일부터 7년 내
B17: ✓ 재산을 도피/ 은닉/ 고의로 재산을 감소한 사유 있음
B18: ✓ 과다한 낭비 또는 도박 등으로 재산 감소 또는 과대한 채무 부담
B19: ✓ 신용거래로 구입한 물건을 현저히 불리한 조건으로 처분
B20: ✓ 특정 채권자에게 특별한 이익을 줄 목적으로 변제한 경우
A21: 2. | B21: 개인회생 신청대상 여부 (법제614호 제1항 제4호 및 제2항 제1호)
B22: ✓ 채무자가 변제할 총 가용소득이 채무자의 개인회생절차 개시결정 당시 보유한 재산 합계액을 상회하여야 함.(가용소득총액>채무총액) | G22: 개인회생신청
B23: ✓ 매달 월급, 연금, 사업소득 등 정기적이고 확실한 수입 가능성 (법 제579조 제1호) | F23: 예
B24: ✓ 무담보채무10억 원, 담보부채무 15억 원을 각각 넘지 않아야 하며 이자 및 지연손해금도 포함 (법 제579조 제1호 가목 및 나목)
B25: ✓ 개인회생 면책 5년 경과
A26: 3. | B26: 사적채무조정(신용회복위원회) 신청대상 여부 | I26: (신용회복위 공통)
B27: ✓ 채무조정 효력이 상실된 날로부터 3개월 이상 경과하지 않은 자 | G27: 신용회복위 신청 | I27: 1) 신청 다음날부터 추심할동 중단
B28: ✓ 채무조정신청이 기각된 날로부터 1년 이상 경과하지 아니한 자 | I28: 2) 신청비 5만원
B29: =B17 | I29: 3) 회원사 신용채무 통합 조정
B30: ✓ 어음·수표 부도거래처로서 부도사유를 해소하지 못한 자 | I30: 4) 방문 즉시 신청(인터넷 신청 가능)
B31: ✓ 협약 외 채무의 원금이 총 채무 원금총액의 20% 이상인 자
B32: ✓ 채무부존재확인소송 또는 대출의 무효·취소를 다투거나 분쟁상태에 있는 자
B33: √ 재산과 수입에 비추어 정상적인 변제가능한 자
B34: ✓ 무담보채무 5억 원, 담보부채무 10억 원 이하(총 15억원 이하)
B35: ✓ 최근 6개월내 신규 발생 채무액이 총 채무액의 30% 이하
B36: ✓ 최저생계비 이상의 수입이 있거나 채무상환이 가능함 | J36: ① 이자(연체이자) 감면
A37: 4. | B37: 사적조정(개인워크아웃) 신청대상 여부 | J37: ② 원금(미상각 채권) 0 ~ 30% 감면
B38: ✓ 연체기간 3개월(90일) 이상 | G38: 적용 가능 | I38: (소득증빙 어려울 경우 가능) | J38: ③ 원금(상각 채권) 20 ~ 70% 감면
A39: 5. | B39: 사적조정(프리워크아웃) 신청대상 여부 | J39: ④ 성실상환(2년 이상) 시 신용정보(공공기록) 삭제
B40: ✓ 금융채무 연체 기간 30일 초과 90일 미만 | G40: 적용 안함 | I40: 금융채무 불이행자(신용불량자) 등록x | J40: ① 약정이자율 30 ~ 70% 내에서 인하
B41: ✓ 최근1년 내 누적 연체일수 30일 이상, 연소득이 4000만원 이하 | I41: 원리금균등상환 | J41: ② 이자율 범위 3.25% ~ 8%
A42: 6. | B42: 사적조정(신속채무조정) 신청대상여부
B43: ✓ 정상이행, 연체 예상, 연체기간 30일 이내 | G43: 적용 안함
B44: ✓ 신청일 현재 최근 6개 월이내 폐업
...

Sheet 신용위 안내문
A1: 안내문
A3: 안녕하십니까
A4: 소상공인시장진흥공단의 희망리턴패키지 사업이 일환으로 시행하는 『2024년 페업(예정) 소상공인 채무조정』 사업을 수행하는 법무법인 덕수입니다.
A5: 그 간 귀하와 본 법무법인의 변호사 및 전문가 사이에 진행하였던 귀하의 '채무조정 신청' 건에 대한 상담(제출하신 자료의 검토를 포함하여)을 통하여 귀하에게 가장 적합한 채무조정 제도로 신용회복위원회의 " "를 자문하였드렸습니다. 귀하의 신속한 채무조정을 위해 아래의 안내에 따라 신용회복위원회 ' '지부에 신청하시기바랍니다.
A7: 1. 방문할 곳 : | C7: 신용회복위원회 | F7: 전화번호 :
B8: 주소 :
A10: 2. 준비할 사항 :
B11: 기본서류 | C11: ①주민등록등본 (뒤 6자라 안보이게, 2개월 이내 발급), ② 신분증
B12: 소득증빙 서류 | C12: 급여소득자 | G12: 자영업자
C13: ① 급여명세서 사본(1년이상) ② 급여통장 입금내역 사본(1년 이상) ③ 근로스득원천징수영수증 사본(전년도) | G13: ① 사업등록증명원 ② 소득금액증명원 ③ 부가가치세과세표준증명원
C14: 소득진술서(소득증빙이 어려운 경우, 별도양식)
B15: 기타 (해당 시) | C15: 재산보유시 간련서류(부동산등기부등본, 자동차증록증 등) 기초수급자, 장애인 등 증빙서류 실업급여 지급결정 통지서, 건강보험자격득실확인서, 건강보험납부증명서 휴직확인서, 폐업증명서(6개월 이내 폐업), 진단서 또는 의사소견서(1개월내 발급)
A17: * 위 '신용회복위원회'에 채무조정 신청 후 접수증 또는 접수비 납부 요청 문자를 받아 이를 법무법인덕수에 송부하시면, 접수 및 비 소정의 교통비를 지급합니다.
B18: 1. 접수증 사본 송부방법
B19: 1) 문자 또는 사진 : 담당자(문자 또는 카카오톡)
B20: 2) 팩스 : 02 - 6280 - 5306 3) 이메일 : restart@iduksu.com
A22: * 위 기관에 접수하는 과정에서 어려움이나 문의사항이 있으면 언제든지 연락해 주십시오
B24: 2024년 월 일
D26: 법무법인 덕수
D27: 담당변호사 :
D28: 담당 사무원 :

Sheet 결과보고서
A1: <별지 4> | C1: 파산·회생 보고서
A3: 채무조정 보고서
A6: □ 자문변호사 정보
A7: 성명 | B7: =상담일지!F11 | D7: 연락처 | E7: 010-3848-5230
A9: □ 신청인 정보
A10: 성명 | B10: =신청서!D6 | D10: 관할센터 | E10: =신청서!E29
A11: 업체명 | B11: =신청서!D7 | D11: 연락처 | E11: =신청서!H8
A12: 업태/종목 | B12: =신청서!H7 | D12: 이메일 | E12: =신청서!D8
A13: 자문장소 | D13: 상담유형 | E13: 유선
A14: 실제 자문일자 | B14: 1차: 12월 11일, 2차: 00월 00일, 3차: 00월 00일
A15: 자 문 내 용
A16: 관련법률조항 | B16: 채무자 회생 및 파산에 관한 법률
A17: 자문결과(요약) | B17: 개인회생신청
A18: 자문결과(상세)
B19: 1. 자문 진행 과정
B20: =신청서!A21 | C20: 소상공시장진흥공단 홈페이지에 '채무조정' 신청
B21: =상담일지!B15 | C21: 채무조정 상담 진행
B23: =상담일지!B33
B24: =상담일지!B34
B25: =상담일지!B35
B27: 2. 기초적 사실관계
B28: 신청인은 2021년 피부관리샵을 창업하여 운영하였으며 코로나 시기에는 매출이 안정적이었으나 코로나 종식 후 매출이 급격히 하락하여 최근 폐업하였음. 현재 건강상의 이유로 약 두 달간 요양이 예정되어 새출발기금 월변제금 80만원 납부가 어려울 것으로 예상됨. 본인명의 자가 빌라(담보 1억 2,000만원, 임차보증금 4,000만원, 시세 약 1억 2,000만원)와 월세보증금 1,000만원을 보유하고 있으며, 배우자가 프리랜서로 근무중이고 자산 처분의사가 있으며 1-2개월 요양 후 소득활동 재개 예정임. 새출발기금 부실차주 2회 연체중임.
B30: 3. 문의사항
B31: 채무조정 방안
B33: 4. 자문내용
B34: 신청인은 과거 채무조정 상담을 통해 새출발기금 부실차주를 신청하였으나 폐업으로 인한 소득 단절로 개인회생을 희망함. 자산의 담보권이 자산가액과 동일하게 설정되어 실질적 무자산 상태로 예상되나 개인회생 신청시 보유 자산의 강제처분 가능성으로 개인회생을 비추천하였으나 신청인이 자산 처분을 희망하므로 자산처분 후 개인회생 진행이 적절함. 경매 절차에서 임차보증금 4,000만원이 소액임차인 최우선변제 대상에 해당하므로 재산권 보장이 가능하며, 요양 후 소득 발생시 개인회생 신청이 가능함을 안내함.
B36: 5. 자문결과 보고
B37: 개인회생신청 예정
B39: 6. 사후권고사항
A42: 첨부자료 | B42: 1. 상담일지 2. 채무조정 신용평가 및 판정표 3. 접수증

Sheet 온라인신청사항
A1: NO | B1: 신청연도 | C1: 차수 | D1: 신청번호 | E1: 진행상태 | F1: 센터명 | G1: 센터담당자 | H1: 신청인 | I1: 생년월일 | J1: 성별 | K1: 전화번호 | L1: 휴대폰 | M1: 이메일 | N1: 사업구분 | O1: 업체명 | P1: 사업자 등록번호 | Q1: 사업장주소 | R1: 사업장주소(상세) | S1: 대분류명 | T1: 중분류명 | U1: 아이템명 | V1: 신청일 | W1: 결과보고서 | X1: 상담신청유형 | Y1: 자문희망일자 | Z1: 제목 | AA1: 변호사이름 | AB1: 변호사연락처 | AC1: 자문 장소 | AD1: 실제 자문일자 1차 | AE1: 실제 자문일자 2차 | AF1: 실제 자문일자 3차 | AG1: 관련법률조항 | AH1: 자문결과(요약) | AI1: 상담신청구분 | AJ1: 사업장소재지 | AK1: 추천기관 | AL1: 상세문의
A2: 4718 | B2: 2025 | C2: 1 | D2: LC00021645 | E2: 접수처리완료 | F2: 고양센터 | G2: 박세훈 | H2: 이향지 | I2: 1988-07-15 | J2: 여 | K2: -- | L2: 010-7501-1482 | M2: thechaeum16@gmail.com | N2: 폐업 | O2: 러블리모먼트 | P2: 548-10-02038 | Q2: 경기도 파주시 경의로 1246 | R2: 유은타워8차 709호 러블리모먼트 | S2: 협회 및 단체, 수리 및 기타 개인 서비스업(94~96) | T2: 기타 개인 서비스업 | U2: 피부 미용업 | V2: 2025-11-30 | X2: 대면 | Y2: 2025-12-10 | Z2: 개인회생신청 | AI2: 채무조정

Sheet 유효성
A1: 예/아니오 | C1: 2023년 기준 중위소득 및 | F1: [시행 2023. 1. 1.] [보건복지부고시 제2022-191호, 2022. 8. 8., 제정.] | M1: 월단위라이프니쯔수치표
A2: 예 | M2: 월 | N2: 라이프니쯔수치
A3: 아니오 | C3: 구분 | D3: 1인가구 | E3: 2인가구 | F3: 3인가구 | G3: 4인가구 | H3: 5인가구 | I3: 6인가구 | J3: 7인가구 | M3: 1 | N3: =(1-POWER((1+5/1200),M3*(-1)))/(5/1200)
C4: 60% 적용 | D4: =D5*0.6 | E4: =E5*0.6 | F4: =F5*0.6 | G4: =G5*0.6 | H4: =H5*0.6 | I4: =I5*0.6 | J4: =J5*0.6 | M4: 2 | N4: =(1-POWER((1+5/1200),M4*(-1)))/(5/1200)
A5: 있음 | C5: 금액(인/월) | D5: 2077892 | E5: 3456155 | F5: 4434816 | G5: 5400964 | H5: 6330688 | I5: 7227981 | J5: 8107515 | M5: 3 | N5: =(1-POWER((1+5/1200),M5*(-1)))/(5/1200)
A6: 없음 | M6: 4 | N6: =(1-POWER((1+5/1200),M6*(-1)))/(5/1200)
C7: 가구 수 | D7: 60% 적용 | E7: 금액(인/월) | M7: 5 | N7: =(1-POWER((1+5/1200),M7*(-1)))/(5/1200)
C8: 1 | D8: =ROUND((E8*0.6),0) | E8: 2077892 | M8: 6 | N8: =(1-POWER((1+5/1200),M8*(-1)))/(5/1200)
A9: 직업 | B9: 결혼 | C9: 2 | D9: =ROUND((E9*0.6),0) | E9: 3456155 | M9: 7 | N9: =(1-POWER((1+5/1200),M9*(-1)))/(5/1200)
A10: 자영 | B10: 기혼 | C10: 3 | D10: =ROUND((E10*0.6),0) | E10: 4434816 | M10: 8 | N10: =(1-POWER((1+5/1200),M10*(-1)))/(5/1200)
A11: 고용 | B11: 미혼 | C11: 4 | D11: =ROUND((E11*0.6),0) | E11: 5400964 | M11: 9 | N11: =(1-POWER((1+5/1200),M11*(-1)))/(5/1200)
A12: 무직 | B12: 이혼 | C12: 5 | D12: =ROUND((E12*0.6),0) | E12: 6330688 | M12: 10 | N12: =(1-POWER((1+5/1200),M12*(-1)))/(5/1200)
B13: 동거 | C13: 6 | D13: =ROUND((E13*0.6),0) | E13: 7227981 | M13: 11 | N13: =(1-POWER((1+5/1200),M13*(-1)))/(5/1200)
C14: 7 | D14: =ROUND((E14*0.6),0) | E14: 8107515 | M14: 12 | N14: =(1-POWER((1+5/1200),M14*(-1)))/(5/1200)
A15: ■ | C15: 8 | M15: 13 | N15: =(1-POWER((1+5/1200),M15*(-1)))/(5/1200)
A16: □ | C16: 9 | M16: 14 | N16: =(1-POWER((1+5/1200),M16*(-1)))/(5/1200)
C17: 10 | M17: 15 | N17: =(1-POWER((1+5/1200),M17*(-1)))/(5/1200)
A18: □ 있음 | M18: 16 | N18: =(1-POWER((1+5/1200),M18*(-1)))/(5/1200)
A19: ■ 있음 | M19: 17 | N19: =(1-POWER((1+5/1200),M19*(-1)))/(5/1200)
A20: □ 없음 | M20: 18 | N20: =(1-POWER((1+5/1200),M20*(-1)))/(5/1200)
A21: ■ 없음 | M21: 19 | N21: =(1-POWER((1+5/1200),M21*(-1)))/(5/1200)
M22: 20 | N22: =(1-POWER((1+5/1200),M22*(-1)))/(5/1200)
M23: 21 | N23: =(1-POWER((1+5/1200),M23*(-1)))/(5/1200)
M24: 22 | N24: =(1-POWER((1+5/1200),M24*(-1)))/(5/1200)
M25: 23 | N25: =(1-POWER((1+5/1200),M25*(-1)))/(5/1200)
M26: 24 | N26: =(1-POWER((1+5/1200),M26*(-1)))/(5/1200)
M27: 25 | N27: =(1-POWER((1+5/1200),M27*(-1)))/(5/1200)
M28: 26 | N28: =(1-POWER((1+5/1200),M28*(-1)))/(5/1200)
M29: 27 | N29: =(1-POWER((1+5/1200),M29*(-1)))/(5/1200)
M30: 28 | N30: =(1-POWER((1+5/1200),M30*(-1)))/(5/1200)
M31: 29 | N31: =(1-POWER((1+5/1200),M31*(-1)))/(5/1200)
M32: 30 | N32: =(1-POWER((1+5/1200),M32*(-1)))/(5/1200)
M33: 31 | N33: =(1-POWER((1+5/1200),M33*(-1)))/(5/1200)
... M62: 60 | N62: =(1-POWER((1+5/1200),M62*(-1)))/(5/1200)
